<mujoco model="neobot_no_mass_matrix">
    <compiler angle="radian" meshdir="../meshes/" />
    <size njmax="500" nconmax="100" />
    <asset>
        <mesh name="base_link" file="base_link.STL" />
        <mesh name="l_hip_roll_link" file="l_hip_roll_link.STL" />
        <mesh name="l_hip_yaw_link" file="l_hip_yaw_link.STL" />
        <mesh name="l_hip_pitch_link" file="l_hip_pitch_link.STL" />
        <mesh name="l_knee_pitch_link" file="l_knee_pitch_link.STL" />
        <mesh name="l_ankle_pitch_link" file="l_ankle_pitch_link.STL" />
        <mesh name="r_hip_roll_link" file="r_hip_roll_link.STL" />
        <mesh name="r_hip_yaw_link" file="r_hip_yaw_link.STL" />
        <mesh name="r_hip_pitch_link" file="r_hip_pitch_link.STL" />
        <mesh name="r_knee_pitch_link" file="r_knee_pitch_link.STL" />
        <mesh name="r_ankle_pitch_link" file="r_ankle_pitch_link.STL" />
    </asset>
    <worldbody>
        <body name="base_link" pos="0 0 0">
            <inertial pos="0.025332 -0.00013939 -0.019715" quat="0.707502 0.706704 -0.00222976 0.00222538" mass="1.0259" diaginertia="0.0040709 0.0039882 0.0013339" />
            <joint name="floating_base_joint" type="free" />
            <geom type="mesh" contype="0" conaffinity="0" group="1" rgba="1 1 1 1" mesh="base_link" />
            <geom size="0.115 0.16 0.1" pos="0.1 0 0" type="box" rgba="1 1 1 1" />
            <body name="l_hip_roll_link" pos="0.0059839 0.1348 -0.050437">
                <inertial pos="0.10952 0.00060667 0.077433" quat="-0.0115147 0.670287 0.0142684 0.741876" mass="0.43907" diaginertia="0.000343379 0.000248039 0.000203652" />
                <joint name="l_hip_roll_joint" pos="0 0 0" axis="1 0 0" limited="true" range="-0.35 0.7" />
                <geom type="mesh" contype="0" conaffinity="0" group="1" rgba="1 1 1 1" mesh="l_hip_roll_link" />
                <body name="l_hip_yaw_link" pos="0.12444 0.0004858 0.1045">
                    <inertial pos="-0.0011389 -9.0175e-05 -0.099938" quat="0.648374 0.257786 0.264702 0.66565" mass="0.79496" diaginertia="0.000615735 0.000372636 0.000352699" />
                    <joint name="l_hip_yaw_joint" pos="0 0 0" axis="0 0 1" limited="true" range="-0.35 0.35" />
                    <geom type="mesh" contype="0" conaffinity="0" group="1" rgba="1 1 1 1" mesh="l_hip_yaw_link" />
                    <body name="l_hip_pitch_link" pos="-0.0016555 0.063239 -0.10747">
                        <inertial pos="0.028914 -0.061567 -0.10564" quat="0.69222 -0.0879632 -0.090323 0.710589" mass="0.26986" diaginertia="0.00222876 0.00211513 0.000115979" />
                        <joint name="l_hip_pitch_joint" pos="0 0 0" axis="0.0261699 -0.999658 0" limited="true" range="-0.7 0.7" />
                        <geom type="mesh" contype="0" conaffinity="0" group="1" rgba="1 1 1 1" mesh="l_hip_pitch_link" />
                        <body name="l_knee_pitch_link" pos="0.069483 -0.067847 -0.26198">
                            <inertial pos="-0.05093 0.014286 -0.094778" quat="0.684719 0.145904 0.150684 0.697973" mass="0.61414" diaginertia="0.00302955 0.00288766 0.000221637" />
                            <joint name="l_knee_pitch_joint" pos="0 0 0" axis="0.0261699 -0.999658 0" limited="true" range="-0.7 0.7" />
                            <geom type="mesh" contype="0" conaffinity="0" group="1" rgba="1 1 1 1" mesh="l_knee_pitch_link" />
                            <body name="l_ankle_pitch_link" pos="-0.11851 -0.00066656 -0.26317">
                                <inertial pos="0.0182969 0.00671075 -0.0230131" quat="0.478131 0.504305 0.523859 0.492584" mass="0.150425" diaginertia="0.000329399 0.000320723 3.26761e-05" />
                                <joint name="l_ankle_pitch_joint" pos="0 0 0" axis="-0.0261699 0.999658 0" limited="true" range="-0.35 0.35" />
                                <geom type="mesh" contype="0" conaffinity="0" group="1" rgba="1 1 1 1" mesh="l_ankle_pitch_link" />
                                <geom size="0.075 0.015 0.005" pos="0.015 0.007 -0.035" type="box" rgba="1 1 1 1" />
                            </body>
                        </body>
                    </body>
                </body>
            </body>
            <body name="r_hip_roll_link" pos="0.0020094 -0.13529 -0.050508">
                <inertial pos="0.11124 -0.0002406 0.077505" quat="-0.0056586 0.669678 0.00676839 0.742599" mass="0.43907" diaginertia="0.000343401 0.000245082 0.000206587" />
                <joint name="r_hip_roll_joint" pos="0 0 0" axis="1 0 0" limited="true" range="-0.7 0.35" />
                <geom type="mesh" contype="0" conaffinity="0" group="1" rgba="1 1 1 1" mesh="r_hip_roll_link" />
                <body name="r_hip_yaw_link" pos="0.12641 0 0.10457">
                    <inertial pos="-0.0014454 3.7879e-05 -0.10005" quat="0.65446 0.29108 0.283471 0.637651" mass="0.79496" diaginertia="0.000615733 0.000374569 0.000350767" />
                    <joint name="r_hip_yaw_joint" pos="0 0 0" axis="0 0 1" limited="true" range="-0.35 0.35" />
                    <geom type="mesh" contype="0" conaffinity="0" group="1" rgba="1 1 1 1" mesh="r_hip_yaw_link" />
                    <body name="r_hip_pitch_link" pos="-0.0015203 -0.063243 -0.10796">
                        <inertial pos="0.0296613 0.0615385 -0.105442" quat="0.710258 -0.092814 -0.0904427 0.69191" mass="0.269855" diaginertia="0.0022288 0.00211513 0.000115978" />
                        <joint name="r_hip_pitch_joint" pos="0 0 0" axis="-0.0261699 -0.999658 0" limited="true" range="-0.7 0.7" />
                        <geom type="mesh" contype="0" conaffinity="0" group="1" rgba="1 1 1 1" mesh="r_hip_pitch_link" />
                        <body name="r_knee_pitch_link" pos="0.070563 0.038225 -0.26149">
                            <inertial pos="-0.050275 0.015498 -0.094854" quat="0.697887 0.150559 0.145744 0.684868" mass="0.61414" diaginertia="0.00302955 0.00289049 0.00021883" />
                            <joint name="r_knee_pitch_joint" pos="0 0 0" axis="-0.0261699 -0.999658 0" limited="true" range="-0.7 0.7" />
                            <geom type="mesh" contype="0" conaffinity="0" group="1" rgba="0.89804 0.91765 0.92941 1" mesh="r_knee_pitch_link" />
                            <body name="r_ankle_pitch_link" pos="-0.11773 0.030653 -0.26317">
                                <inertial pos="0.0183208 -0.00579655 -0.0230131" quat="0.490858 0.517842 0.510482 0.479903" mass="0.150425" diaginertia="0.000329399 0.000320723 3.26761e-05" />
                                <joint name="r_ankle_pitch_joint" pos="0 0 0" axis="-0.0261699 -0.999658 0" limited="true" range="-0.35 0.35" />
                                <geom type="mesh" contype="0" conaffinity="0" group="1" rgba="1 1 1 1" mesh="r_ankle_pitch_link" />
                                <geom size="0.075 0.015 0.005" pos="0.015 -0.007 -0.035" type="box" rgba="1 1 1 1" />
                            </body>
                        </body>
                    </body>
                </body>
            </body>
        </body>
    </worldbody>
</mujoco>
