<?xml version="1.0" encoding="utf-8"?>
<!-- This URDF was automatically created by SolidWorks to URDF Exporter! Originally created by Stephen Brawner (brawner@gmail.com) 
     Commit Version: 1.6.0-4-g7f85cfe  Build Version: 1.6.7995.38578
     For more information, please see http://wiki.ros.org/sw_urdf_exporter -->
<robot
  name="neobot_no_mass_matrix">
  <mujoco>
    <compiler 
    meshdir="../meshes/" 
    balanceinertia="true" 
    discardvisual="false" />
  </mujoco>

  <!-- [CAUTION] uncomment when convert to mujoco -->
  <link name="world"></link>
  <joint name="floating_base_joint" type="floating">
    <parent link="world" />
    <child link="base_link" />
  </joint>
  <link
    name="base_link">
    <inertial>
      <origin
        xyz="0.025332 -0.00013939 -0.019715"
        rpy="0 0 0" />
      <mass
        value="1.0259" />
      <inertia
        ixx="0.0040709"
        ixy="-2.6093E-08"
        ixz="5.2109E-07"
        iyy="0.0013339"
        iyz="2.9974E-06"
        izz="0.0039882" />
    </inertial>
    <visual>
      <origin
        xyz="0 0 0"
        rpy="0 0 0" />
      <geometry>
        <mesh
          filename="../meshes/base_link.STL" />
      </geometry>
      <material
        name="">
        <color
          rgba="1 1 1 1" />
      </material>
    </visual>
    <collision>
      <origin
        xyz="0.1 0 0"
        rpy="0 0 0" />
      <geometry>
        <!-- <mesh
          filename="../meshes/base_link.STL" /> -->
        <box size="0.23 0.32 0.2" />
      </geometry>
    </collision>
  </link>
  <link
    name="l_hip_roll_link">
    <inertial>
      <origin
        xyz="0.10952 0.00060667 0.077433"
        rpy="0 0 0" />
      <mass
        value="0.43907" />
      <inertia
        ixx="0.00020514"
        ixy="-1.6352E-06"
        ixz="-1.4054E-05"
        iyy="0.00024798"
        iyz="2.9614E-08"
        izz="0.00034195" />
    </inertial>
    <visual>
      <origin
        xyz="0 0 0"
        rpy="0 0 0" />
      <geometry>
        <mesh
          filename="../meshes/l_hip_roll_link.STL" />
      </geometry>
      <material
        name="">
        <color
          rgba="1 1 1 1" />
      </material>
    </visual>
    
  </link>
  <joint
    name="l_hip_roll_joint"
    type="revolute">
    <origin
      xyz="0.0059839 0.1348 -0.050437"
      rpy="0 0 0" />
    <parent
      link="base_link" />
    <child
      link="l_hip_roll_link" />
    <axis
      xyz="1 0 0" />
    <limit
      lower="-0.35"
      upper="0.7"
      effort="12"
      velocity="25" />
  </joint>
  <link
    name="l_hip_yaw_link">
    <inertial>
      <origin
        xyz="-0.0011389 -9.0175E-05 -0.099938"
        rpy="0 0 0" />
      <mass
        value="0.79496" />
      <inertia
        ixx="0.00036341"
        ixy="-6.6426E-06"
        ixz="-9.9482E-06"
        iyy="0.00061556"
        iyz="-2.7749E-07"
        izz="0.0003621" />
    </inertial>
    <visual>
      <origin
        xyz="0 0 0"
        rpy="0 0 0" />
      <geometry>
        <mesh
          filename="../meshes/l_hip_yaw_link.STL" />
      </geometry>
      <material
        name="">
        <color
          rgba="1 1 1 1" />
      </material>
    </visual>
    
  </link>
  <joint
    name="l_hip_yaw_joint"
    type="revolute">
    <origin
      xyz="0.12444 0.0004858 0.1045"
      rpy="0 0 0" />
    <parent
      link="l_hip_roll_link" />
    <child
      link="l_hip_yaw_link" />
    <axis
      xyz="0 0 1" />
    <limit
      lower="-0.35"
      upper="0.35"
      effort="12"
      velocity="25" />
  </joint>
  <link
    name="l_hip_pitch_link">
    <inertial>
      <origin
        xyz="0.028914 -0.061567 -0.10564"
        rpy="0 0 0" />
      <mass
        value="0.26986" />
      <inertia
        ixx="0.0019902"
        ixy="-6.2669E-06"
        ixz="0.00048401"
        iyy="0.0022286"
        iyz="1.275E-05"
        izz="0.00024107" />
    </inertial>
    <visual>
      <origin
        xyz="0 0 0"
        rpy="0 0 0" />
      <geometry>
        <mesh
          filename="../meshes/l_hip_pitch_link.STL" />
      </geometry>
      <material
        name="">
        <color
          rgba="1 1 1 1" />
      </material>
    </visual>
    
  </link>
  <joint
    name="l_hip_pitch_joint"
    type="revolute">
    <origin
      xyz="-0.0016555 0.063239 -0.10747"
      rpy="0 0 0" />
    <parent
      link="l_hip_yaw_link" />
    <child
      link="l_hip_pitch_link" />
    <axis
      xyz="0.02617 -0.99966 0" />
    <limit
      lower="-0.7"
      upper="0.7"
      effort="12"
      velocity="25" />
  </joint>
  <link
    name="l_knee_pitch_link">
    <inertial>
      <origin
        xyz="-0.05093 0.014286 -0.094778"
        rpy="0 0 0" />
      <mass
        value="0.61414" />
      <inertia
        ixx="0.0024395"
        ixy="-1.4322E-05"
        ixz="-0.00099695"
        iyy="0.0030292"
        iyz="-2.6006E-05"
        izz="0.00067015" />
    </inertial>
    <visual>
      <origin
        xyz="0 0 0"
        rpy="0 0 0" />
      <geometry>
        <mesh
          filename="../meshes/l_knee_pitch_link.STL" />
      </geometry>
      <material
        name="">
        <color
          rgba="1 1 1 1" />
      </material>
    </visual>
    
  </link>
  <joint
    name="l_knee_pitch_joint"
    type="revolute">
    <origin
      xyz="0.069483 -0.067847 -0.26198"
      rpy="0 0 0" />
    <parent
      link="l_hip_pitch_link" />
    <child
      link="l_knee_pitch_link" />
    <axis
      xyz="0.02617 -0.99966 0" />
    <limit
      lower="-0.7"
      upper="0.7"
      effort="12"
      velocity="25" />
  </joint>
  <link
    name="l_ankle_pitch_link">
    <inertial>
      <origin
        xyz="0.0182968915849038 0.00671074692625817 -0.0230131226592281"
        rpy="0 0 0" />
      <mass
        value="0.150424633030641" />
      <inertia
        ixx="3.39685529656541E-05"
        ixy="-1.00223126318698E-05"
        ixz="1.65280472263256E-05"
        iyy="0.000329059253769662"
        iyz="5.24825584617872E-07"
        izz="0.00031977114492758" />
    </inertial>
    <visual>
      <origin
        xyz="0 0 0"
        rpy="0 0 0" />
      <geometry>
        <mesh
          filename="../meshes/l_ankle_pitch_link.STL" />
      </geometry>
      <material
        name="">
        <color
          rgba="1 1 1 1" />
      </material>
    </visual>
    <collision
      name="l_ankle_pitch_link_collision">
      <origin
        xyz="0.015 0.007 -0.035"
        rpy="0 0 0" />
      <geometry>
        <!-- <mesh
          filename="../meshes/r_ankle_pitch_link.STL" /> -->
          <box
            size="0.15 0.03 0.01" />
      </geometry>
    </collision>
  </link>
  <joint
    name="l_ankle_pitch_joint"
    type="revolute">
    <origin
      xyz="-0.11851 -0.00066656 -0.26317"
      rpy="0 0 0" />
    <parent
      link="l_knee_pitch_link" />
    <child
      link="l_ankle_pitch_link" />
    <axis
      xyz="-0.02617 0.99966 0" />
    <limit
      lower="-0.35"
      upper="0.35"
      effort="12"
      velocity="25" />
  </joint>
  <link
    name="r_hip_roll_link">
    <inertial>
      <origin
        xyz="0.11124 -0.0002406 0.077505"
        rpy="0 0 0" />
      <mass
        value="0.43907" />
      <inertia
        ixx="0.00020805"
        ixy="-6.817E-07"
        ixz="-1.4015E-05"
        iyy="0.00024507"
        iyz="-5.2307E-09"
        izz="0.00034195" />
    </inertial>
    <visual>
      <origin
        xyz="0 0 0"
        rpy="0 0 0" />
      <geometry>
        <mesh
          filename="../meshes/r_hip_roll_link.STL" />
      </geometry>
      <material
        name="">
        <color
          rgba="1 1 1 1" />
      </material>
    </visual>
    
  </link>
  <joint
    name="r_hip_roll_joint"
    type="revolute">
    <origin
      xyz="0.0020094 -0.13529 -0.050508"
      rpy="0 0 0" />
    <parent
      link="base_link" />
    <child
      link="r_hip_roll_link" />
    <axis
      xyz="1 0 0" />
    <limit
      lower="-0.7"
      upper="0.35"
      effort="12"
      velocity="25" />
  </joint>
  <link
    name="r_hip_yaw_link">
    <inertial>
      <origin
        xyz="-0.0014454 3.7879E-05 -0.10005"
        rpy="0 0 0" />
      <mass
        value="0.79496" />
      <inertia
        ixx="0.00036162"
        ixy="6.6346E-06"
        ixz="-1.1833E-05"
        iyy="0.00061556"
        iyz="3.5286E-07"
        izz="0.00036389" />
    </inertial>
    <visual>
      <origin
        xyz="0 0 0"
        rpy="0 0 0" />
      <geometry>
        <mesh
          filename="../meshes/r_hip_yaw_link.STL" />
      </geometry>
      <material
        name="">
        <color
          rgba="1 1 1 1" />
      </material>
    </visual>
    
  </link>
  <joint
    name="r_hip_yaw_joint"
    type="revolute">
    <origin
      xyz="0.12641 0 0.10457"
      rpy="0 0 0" />
    <parent
      link="r_hip_roll_link" />
    <child
      link="r_hip_yaw_link" />
    <axis
      xyz="0 0 1" />
    <limit
      lower="-0.35"
      upper="0.35"
      effort="12"
      velocity="25" />
  </joint>
  <link
    name="r_hip_pitch_link">
    <inertial>
      <origin
        xyz="0.0296613029326732 0.0615385133216562 -0.105441901990499"
        rpy="0 0 0" />
      <mass
        value="0.269855469121405" />
      <inertia
        ixx="0.00198325131710804"
        ixy="6.40714270998516E-06"
        ixz="0.000496356338465778"
        iyy="0.00222863110875713"
        iyz="-1.29149112081268E-05"
        izz="0.000248019984218983" />
    </inertial>
    <visual>
      <origin
        xyz="0 0 0"
        rpy="0 0 0" />
      <geometry>
        <mesh
          filename="../meshes/r_hip_pitch_link.STL" />
      </geometry>
      <material
        name="">
        <color
          rgba="1 1 1 1" />
      </material>
    </visual>
    
  </link>
  <joint
    name="r_hip_pitch_joint"
    type="revolute">
    <origin
      xyz="-0.0015203 -0.063243 -0.10796"
      rpy="0 0 0" />
    <parent
      link="r_hip_yaw_link" />
    <child
      link="r_hip_pitch_link" />
    <axis
      xyz="-0.02617 -0.99966 0" />
    <limit
      lower="-0.7"
      upper="0.7"
      effort="12"
      velocity="25" />
  </joint>
  <link
    name="r_knee_pitch_link">
    <inertial>
      <origin
        xyz="-0.050275 0.015498 -0.094854"
        rpy="0 0 0" />
      <mass
        value="0.61414" />
      <inertia
        ixx="0.0024422"
        ixy="1.421E-05"
        ixz="-0.00099833"
        iyy="0.0030292"
        iyz="2.6016E-05"
        izz="0.00066747" />
    </inertial>
    <visual>
      <origin
        xyz="0 0 0"
        rpy="0 0 0" />
      <geometry>
        <mesh
          filename="../meshes/r_knee_pitch_link.STL" />
      </geometry>
      <material
        name="">
        <color
          rgba="0.89804 0.91765 0.92941 1" />
      </material>
    </visual>
    
  </link>
  <joint
    name="r_knee_pitch_joint"
    type="revolute">
    <origin
      xyz="0.070563 0.038225 -0.26149"
      rpy="0 0 0" />
    <parent
      link="r_hip_pitch_link" />
    <child
      link="r_knee_pitch_link" />
    <axis
      xyz="-0.02617 -0.99966 0" />
    <limit
      lower="-0.7"
      upper="0.7"
      effort="12"
      velocity="25" />
  </joint>
  <link
    name="r_ankle_pitch_link">
    <inertial>
      <origin
        xyz="0.0183208247116615 -0.0057965458968319 -0.0230131226546726"
        rpy="0 0 0" />
      <mass
        value="0.150424633173082" />
      <inertia
        ixx="3.37290578699588E-05"
        ixy="5.45129807480738E-06"
        ixz="1.65328679786539E-05"
        iyy="0.000329298749429327"
        iyz="-3.40681507625098E-07"
        izz="0.000319771145413726" />
    </inertial>
    <visual>
      <origin
        xyz="0 0 0"
        rpy="0 0 0" />
      <geometry>
        <mesh
          filename="../meshes/r_ankle_pitch_link.STL" />
      </geometry>
      <material
        name="">
        <color
          rgba="1 1 1 1" />
      </material>
    </visual>
    <collision
      name="r_ankle_pitch_link_collision">
      <origin
        xyz="0.015 -0.007 -0.035"
        rpy="0 0 0" />
      <geometry>
        <!-- <mesh
          filename="../meshes/r_ankle_pitch_link.STL" /> -->
          <box
            size="0.15 0.03 0.01" />
      </geometry>
    </collision>
  </link>
  <joint
    name="r_ankle_pitch_joint"
    type="revolute">
    <origin
      xyz="-0.11773 0.030653 -0.26317"
      rpy="0 0 0" />
    <parent
      link="r_knee_pitch_link" />
    <child
      link="r_ankle_pitch_link" />
    <axis
      xyz="-0.02617 -0.99966 0" />
    <limit
      lower="-0.35"
      upper="0.35"
      effort="12"
      velocity="25" />
  </joint>
</robot>
